[2021-11-21 13:13:23,635] {taskinstance.py:1035} INFO - Dependencies all met for <TaskInstance: postgres_operator_dag.create_pet_table manual__2021-11-21T06:12:57.454204+00:00 [queued]>
[2021-11-21 13:13:23,642] {taskinstance.py:1035} INFO - Dependencies all met for <TaskInstance: postgres_operator_dag.create_pet_table manual__2021-11-21T06:12:57.454204+00:00 [queued]>
[2021-11-21 13:13:23,643] {taskinstance.py:1241} INFO - 
--------------------------------------------------------------------------------
[2021-11-21 13:13:23,643] {taskinstance.py:1242} INFO - Starting attempt 1 of 1
[2021-11-21 13:13:23,643] {taskinstance.py:1243} INFO - 
--------------------------------------------------------------------------------
[2021-11-21 13:13:23,664] {taskinstance.py:1262} INFO - Executing <Task(PostgresOperator): create_pet_table> on 2021-11-21 06:12:57.454204+00:00
[2021-11-21 13:13:23,668] {standard_task_runner.py:52} INFO - Started process 37675 to run task
[2021-11-21 13:13:23,676] {standard_task_runner.py:76} INFO - Running: ['airflow', 'tasks', 'run', 'postgres_operator_dag', 'create_pet_table', 'manual__2021-11-21T06:12:57.454204+00:00', '--job-id', '10', '--raw', '--subdir', 'DAGS_FOLDER/run_psql.py', '--cfg-path', '/tmp/tmp1zoxzb1w', '--error-file', '/tmp/tmp1s6u3uv0']
[2021-11-21 13:13:23,677] {standard_task_runner.py:77} INFO - Job 10: Subtask create_pet_table
[2021-11-21 13:13:23,711] {logging_mixin.py:109} INFO - Running <TaskInstance: postgres_operator_dag.create_pet_table manual__2021-11-21T06:12:57.454204+00:00 [running]> on host ubuntu2110.linuxvmimages.local
[2021-11-21 13:13:23,738] {taskinstance.py:1427} INFO - Exporting the following env vars:
AIRFLOW_CTX_DAG_OWNER=airflow
AIRFLOW_CTX_DAG_ID=postgres_operator_dag
AIRFLOW_CTX_TASK_ID=create_pet_table
AIRFLOW_CTX_EXECUTION_DATE=2021-11-21T06:12:57.454204+00:00
AIRFLOW_CTX_DAG_RUN_ID=manual__2021-11-21T06:12:57.454204+00:00
[2021-11-21 13:13:23,741] {base.py:70} INFO - Using connection to: id: postgres_default. Host: postgres, Port: None, Schema: ***, Login: postgres, Password: ***, extra: {}
[2021-11-21 13:13:44,904] {taskinstance.py:1703} ERROR - Task failed with exception
Traceback (most recent call last):
  File "/usr/local/lib/python3.9/dist-packages/airflow/models/taskinstance.py", line 1332, in _run_raw_task
    self._execute_task_with_callbacks(context)
  File "/usr/local/lib/python3.9/dist-packages/airflow/models/taskinstance.py", line 1458, in _execute_task_with_callbacks
    result = self._execute_task(context, self.task)
  File "/usr/local/lib/python3.9/dist-packages/airflow/models/taskinstance.py", line 1514, in _execute_task
    result = execute_callable(context=context)
  File "/usr/local/lib/python3.9/dist-packages/airflow/providers/postgres/operators/postgres.py", line 69, in execute
    self.hook.run(self.sql, self.autocommit, parameters=self.parameters)
  File "/usr/local/lib/python3.9/dist-packages/airflow/hooks/dbapi.py", line 198, in run
    with closing(self.get_conn()) as conn:
  File "/usr/local/lib/python3.9/dist-packages/airflow/providers/postgres/hooks/postgres.py", line 115, in get_conn
    self.conn = psycopg2.connect(**conn_args)
  File "/usr/local/lib/python3.9/dist-packages/psycopg2/__init__.py", line 122, in connect
    conn = _connect(dsn, connection_factory=connection_factory, **kwasync)
psycopg2.OperationalError: connection to server at "postgres" (36.86.63.182), port 5432 failed: Connection refused
	Is the server running on that host and accepting TCP/IP connections?

[2021-11-21 13:13:44,910] {taskinstance.py:1270} INFO - Marking task as FAILED. dag_id=postgres_operator_dag, task_id=create_pet_table, execution_date=20211121T061257, start_date=20211121T061323, end_date=20211121T061344
[2021-11-21 13:13:44,918] {standard_task_runner.py:88} ERROR - Failed to execute job 10 for task create_pet_table
Traceback (most recent call last):
  File "/usr/local/lib/python3.9/dist-packages/airflow/task/task_runner/standard_task_runner.py", line 85, in _start_by_fork
    args.func(args, dag=self.dag)
  File "/usr/local/lib/python3.9/dist-packages/airflow/cli/cli_parser.py", line 48, in command
    return func(*args, **kwargs)
  File "/usr/local/lib/python3.9/dist-packages/airflow/utils/cli.py", line 92, in wrapper
    return f(*args, **kwargs)
  File "/usr/local/lib/python3.9/dist-packages/airflow/cli/commands/task_command.py", line 292, in task_run
    _run_task_by_selected_method(args, dag, ti)
  File "/usr/local/lib/python3.9/dist-packages/airflow/cli/commands/task_command.py", line 107, in _run_task_by_selected_method
    _run_raw_task(args, ti)
  File "/usr/local/lib/python3.9/dist-packages/airflow/cli/commands/task_command.py", line 180, in _run_raw_task
    ti._run_raw_task(
  File "/usr/local/lib/python3.9/dist-packages/airflow/utils/session.py", line 70, in wrapper
    return func(*args, session=session, **kwargs)
  File "/usr/local/lib/python3.9/dist-packages/airflow/models/taskinstance.py", line 1332, in _run_raw_task
    self._execute_task_with_callbacks(context)
  File "/usr/local/lib/python3.9/dist-packages/airflow/models/taskinstance.py", line 1458, in _execute_task_with_callbacks
    result = self._execute_task(context, self.task)
  File "/usr/local/lib/python3.9/dist-packages/airflow/models/taskinstance.py", line 1514, in _execute_task
    result = execute_callable(context=context)
  File "/usr/local/lib/python3.9/dist-packages/airflow/providers/postgres/operators/postgres.py", line 69, in execute
    self.hook.run(self.sql, self.autocommit, parameters=self.parameters)
  File "/usr/local/lib/python3.9/dist-packages/airflow/hooks/dbapi.py", line 198, in run
    with closing(self.get_conn()) as conn:
  File "/usr/local/lib/python3.9/dist-packages/airflow/providers/postgres/hooks/postgres.py", line 115, in get_conn
    self.conn = psycopg2.connect(**conn_args)
  File "/usr/local/lib/python3.9/dist-packages/psycopg2/__init__.py", line 122, in connect
    conn = _connect(dsn, connection_factory=connection_factory, **kwasync)
psycopg2.OperationalError: connection to server at "postgres" (36.86.63.182), port 5432 failed: Connection refused
	Is the server running on that host and accepting TCP/IP connections?

[2021-11-21 13:13:44,951] {local_task_job.py:154} INFO - Task exited with return code 1
[2021-11-21 13:13:44,960] {local_task_job.py:264} INFO - 0 downstream tasks scheduled from follow-on schedule check
